<?xml version="1.0" encoding="UTF-8"?>
<!-- Generated by org.testng.reporters.JUnitReportReporter -->
<testsuite hostname="DESKTOP-KCVLOK6" failures="1" tests="13" name="examplePackageForTestNg.CalculatorTest2" time="0.232" errors="2" timestamp="24 Mar 2022 17:51:08 GMT">
  <testcase classname="examplePackageForTestNg.CalculatorTest2" name="add0TestDP" time="0.008"/>
  <testcase classname="examplePackageForTestNg.CalculatorTest2" name="add0TestDP" time="0.036"/>
  <testcase classname="examplePackageForTestNg.CalculatorTest2" name="add4Test" time="0.000"/>
  <testcase classname="examplePackageForTestNg.CalculatorTest2" name="add0TestDP" time="0.042"/>
  <testcase classname="examplePackageForTestNg.CalculatorTest2" name="add2Test" time="0.017">
    <error message="expected [9] but found [11]" type="java.lang.AssertionError">
      <![CDATA[java.lang.AssertionError: expected [9] but found [11]
	at org.testng.Assert.fail(Assert.java:94)
	at org.testng.Assert.failNotEquals(Assert.java:494)
	at org.testng.Assert.assertEquals(Assert.java:123)
	at org.testng.Assert.assertEquals(Assert.java:370)
	at org.testng.Assert.assertEquals(Assert.java:380)
	at examplePackageForTestNg.CalculatorTest2.add2Test(CalculatorTest2.java:21)
	at java.base/jdk.internal.reflect.NativeMethodAccessorImpl.invoke0(Native Method)
	at java.base/jdk.internal.reflect.NativeMethodAccessorImpl.invoke(NativeMethodAccessorImpl.java:77)
	at java.base/jdk.internal.reflect.DelegatingMethodAccessorImpl.invoke(DelegatingMethodAccessorImpl.java:43)
	at java.base/java.lang.reflect.Method.invoke(Method.java:568)
	at org.testng.internal.MethodInvocationHelper.invokeMethod(MethodInvocationHelper.java:84)
	at org.testng.internal.Invoker.invokeMethod(Invoker.java:714)
	at org.testng.internal.Invoker.invokeTestMethod(Invoker.java:901)
	at org.testng.internal.Invoker.invokeTestMethods(Invoker.java:1231)
	at org.testng.internal.TestMethodWorker.invokeTestMethods(TestMethodWorker.java:127)
	at org.testng.internal.TestMethodWorker.run(TestMethodWorker.java:111)
	at java.base/java.util.concurrent.ThreadPoolExecutor.runWorker(ThreadPoolExecutor.java:1136)
	at java.base/java.util.concurrent.ThreadPoolExecutor$Worker.run(ThreadPoolExecutor.java:635)
	at java.base/java.lang.Thread.run(Thread.java:833)
]]>
    </error>
  </testcase> <!-- add2Test -->
  <testcase classname="examplePackageForTestNg.CalculatorTest2" name="add0TestDP" time="0.010"/>
  <testcase classname="examplePackageForTestNg.CalculatorTest2" name="add1Test" time="0.013"/>
  <testcase classname="examplePackageForTestNg.CalculatorTest2" name="devideByZeroTest" time="0.011"/>
  <testcase classname="examplePackageForTestNg.CalculatorTest2" name="sub2Test" time="0.007"/>
  <testcase classname="examplePackageForTestNg.CalculatorTest2" name="add3Test" time="0.075"/>
  <testcase classname="examplePackageForTestNg.CalculatorTest2" name="mul1Test" time="0.004"/>
  <testcase classname="examplePackageForTestNg.CalculatorTest2" name="add0TestDP" time="0.005">
    <error message="expected [10] but found [11]" type="java.lang.AssertionError">
      <![CDATA[java.lang.AssertionError: expected [10] but found [11]
	at org.testng.Assert.fail(Assert.java:94)
	at org.testng.Assert.failNotEquals(Assert.java:494)
	at org.testng.Assert.assertEquals(Assert.java:123)
	at org.testng.Assert.assertEquals(Assert.java:370)
	at org.testng.Assert.assertEquals(Assert.java:380)
	at examplePackageForTestNg.CalculatorTest2.add0TestDP(CalculatorTest2.java:59)
	at java.base/jdk.internal.reflect.NativeMethodAccessorImpl.invoke0(Native Method)
	at java.base/jdk.internal.reflect.NativeMethodAccessorImpl.invoke(NativeMethodAccessorImpl.java:77)
	at java.base/jdk.internal.reflect.DelegatingMethodAccessorImpl.invoke(DelegatingMethodAccessorImpl.java:43)
	at java.base/java.lang.reflect.Method.invoke(Method.java:568)
	at org.testng.internal.MethodInvocationHelper.invokeMethod(MethodInvocationHelper.java:84)
	at org.testng.internal.Invoker.invokeMethod(Invoker.java:714)
	at org.testng.internal.Invoker.invokeTestMethod(Invoker.java:901)
	at org.testng.internal.Invoker.invokeTestMethods(Invoker.java:1231)
	at org.testng.internal.TestMethodWorker.invokeTestMethods(TestMethodWorker.java:127)
	at org.testng.internal.TestMethodWorker.run(TestMethodWorker.java:111)
	at java.base/java.util.concurrent.ThreadPoolExecutor.runWorker(ThreadPoolExecutor.java:1136)
	at java.base/java.util.concurrent.ThreadPoolExecutor$Worker.run(ThreadPoolExecutor.java:635)
	at java.base/java.lang.Thread.run(Thread.java:833)
]]>
    </error>
  </testcase> <!-- add0TestDP -->
  <testcase classname="examplePackageForTestNg.CalculatorTest2" name="sub1Test" time="0.004"/>
</testsuite> <!-- examplePackageForTestNg.CalculatorTest2 -->
